2024-12-02 09:43:32,915 - __main__ - INFO - Bot is polling...
2024-12-02 09:43:34,569 - httpx - INFO - HTTP Request: POST https://api.telegram.org/bot7617596594:AAFyiPhJU4lcaBsbFgdTjdxKPPXV4dHiUqI/getMe "HTTP/1.1 200 OK"
2024-12-02 09:43:34,761 - httpx - INFO - HTTP Request: POST https://api.telegram.org/bot7617596594:AAFyiPhJU4lcaBsbFgdTjdxKPPXV4dHiUqI/deleteWebhook "HTTP/1.1 200 OK"
2024-12-02 09:43:34,766 - telegram.ext.Application - INFO - Application started
2024-12-02 09:43:35,396 - httpx - INFO - HTTP Request: POST https://api.telegram.org/bot7617596594:AAFyiPhJU4lcaBsbFgdTjdxKPPXV4dHiUqI/getUpdates "HTTP/1.1 200 OK"
2024-12-02 09:43:46,473 - __main__ - ERROR - Exception while handling an update:
Traceback (most recent call last):
  File "D:\Magang\bot-tele\venv\lib\site-packages\httpx\_transports\default.py", line 72, in map_httpcore_exceptions
    yield
  File "D:\Magang\bot-tele\venv\lib\site-packages\httpx\_transports\default.py", line 377, in handle_async_request
    resp = await self._pool.handle_async_request(req)
  File "D:\Magang\bot-tele\venv\lib\site-packages\httpcore\_async\connection_pool.py", line 216, in handle_async_request
    raise exc from None
  File "D:\Magang\bot-tele\venv\lib\site-packages\httpcore\_async\connection_pool.py", line 196, in handle_async_request
    response = await connection.handle_async_request(
  File "D:\Magang\bot-tele\venv\lib\site-packages\httpcore\_async\connection.py", line 99, in handle_async_request
    raise exc
  File "D:\Magang\bot-tele\venv\lib\site-packages\httpcore\_async\connection.py", line 76, in handle_async_request
    stream = await self._connect(request)
  File "D:\Magang\bot-tele\venv\lib\site-packages\httpcore\_async\connection.py", line 122, in _connect
    stream = await self._network_backend.connect_tcp(**kwargs)
  File "D:\Magang\bot-tele\venv\lib\site-packages\httpcore\_backends\auto.py", line 30, in connect_tcp
    return await self._backend.connect_tcp(
  File "D:\Magang\bot-tele\venv\lib\site-packages\httpcore\_backends\anyio.py", line 115, in connect_tcp
    with map_exceptions(exc_map):
  File "C:\Users\kahfi\AppData\Local\Programs\Python\Python310\lib\contextlib.py", line 153, in __exit__
    self.gen.throw(typ, value, traceback)
  File "D:\Magang\bot-tele\venv\lib\site-packages\httpcore\_exceptions.py", line 14, in map_exceptions
    raise to_exc(exc) from exc
httpcore.ConnectError: [Errno 11001] getaddrinfo failed

The above exception was the direct cause of the following exception:

Traceback (most recent call last):
  File "D:\Magang\bot-tele\venv\lib\site-packages\telegram\request\_httpxrequest.py", line 292, in do_request
    res = await self._client.request(
  File "D:\Magang\bot-tele\venv\lib\site-packages\httpx\_client.py", line 1585, in request
    return await self.send(request, auth=auth, follow_redirects=follow_redirects)
  File "D:\Magang\bot-tele\venv\lib\site-packages\httpx\_client.py", line 1674, in send
    response = await self._send_handling_auth(
  File "D:\Magang\bot-tele\venv\lib\site-packages\httpx\_client.py", line 1702, in _send_handling_auth
    response = await self._send_handling_redirects(
  File "D:\Magang\bot-tele\venv\lib\site-packages\httpx\_client.py", line 1739, in _send_handling_redirects
    response = await self._send_single_request(request)
  File "D:\Magang\bot-tele\venv\lib\site-packages\httpx\_client.py", line 1776, in _send_single_request
    response = await transport.handle_async_request(request)
  File "D:\Magang\bot-tele\venv\lib\site-packages\httpx\_transports\default.py", line 376, in handle_async_request
    with map_httpcore_exceptions():
  File "C:\Users\kahfi\AppData\Local\Programs\Python\Python310\lib\contextlib.py", line 153, in __exit__
    self.gen.throw(typ, value, traceback)
  File "D:\Magang\bot-tele\venv\lib\site-packages\httpx\_transports\default.py", line 89, in map_httpcore_exceptions
    raise mapped_exc(message) from exc
httpx.ConnectError: [Errno 11001] getaddrinfo failed

The above exception was the direct cause of the following exception:

Traceback (most recent call last):
  File "D:\Magang\bot-tele\venv\lib\site-packages\telegram\ext\_application.py", line 1335, in process_update
    await coroutine
  File "D:\Magang\bot-tele\venv\lib\site-packages\telegram\ext\_handlers\basehandler.py", line 158, in handle_update
    return await self.callback(update, context)
  File "D:\Magang\bot-tele\bot_telegram\commands.py", line 41, in start
    await update.message.reply_text("Failed to connect to the database.")
  File "D:\Magang\bot-tele\venv\lib\site-packages\telegram\_message.py", line 1762, in reply_text
    return await self.get_bot().send_message(
  File "D:\Magang\bot-tele\venv\lib\site-packages\telegram\ext\_extbot.py", line 2909, in send_message
    return await super().send_message(
  File "D:\Magang\bot-tele\venv\lib\site-packages\telegram\_bot.py", line 1029, in send_message
    return await self._send_message(
  File "D:\Magang\bot-tele\venv\lib\site-packages\telegram\ext\_extbot.py", line 610, in _send_message
    result = await super()._send_message(
  File "D:\Magang\bot-tele\venv\lib\site-packages\telegram\_bot.py", line 745, in _send_message
    result = await self._post(
  File "D:\Magang\bot-tele\venv\lib\site-packages\telegram\_bot.py", line 623, in _post
    return await self._do_post(
  File "D:\Magang\bot-tele\venv\lib\site-packages\telegram\ext\_extbot.py", line 355, in _do_post
    return await super()._do_post(
  File "D:\Magang\bot-tele\venv\lib\site-packages\telegram\_bot.py", line 652, in _do_post
    result = await request.post(
  File "D:\Magang\bot-tele\venv\lib\site-packages\telegram\request\_baserequest.py", line 201, in post
    result = await self._request_wrapper(
  File "D:\Magang\bot-tele\venv\lib\site-packages\telegram\request\_baserequest.py", line 333, in _request_wrapper
    code, payload = await self.do_request(
  File "D:\Magang\bot-tele\venv\lib\site-packages\telegram\request\_httpxrequest.py", line 316, in do_request
    raise NetworkError(f"httpx.{err.__class__.__name__}: {err}") from err
telegram.error.NetworkError: httpx.ConnectError: [Errno 11001] getaddrinfo failed
2024-12-02 09:43:49,185 - __main__ - ERROR - Exception while handling an update:
Traceback (most recent call last):
  File "D:\Magang\bot-tele\venv\lib\site-packages\httpx\_transports\default.py", line 72, in map_httpcore_exceptions
    yield
  File "D:\Magang\bot-tele\venv\lib\site-packages\httpx\_transports\default.py", line 377, in handle_async_request
    resp = await self._pool.handle_async_request(req)
  File "D:\Magang\bot-tele\venv\lib\site-packages\httpcore\_async\connection_pool.py", line 216, in handle_async_request
    raise exc from None
  File "D:\Magang\bot-tele\venv\lib\site-packages\httpcore\_async\connection_pool.py", line 196, in handle_async_request
    response = await connection.handle_async_request(
  File "D:\Magang\bot-tele\venv\lib\site-packages\httpcore\_async\connection.py", line 99, in handle_async_request
    raise exc
  File "D:\Magang\bot-tele\venv\lib\site-packages\httpcore\_async\connection.py", line 76, in handle_async_request
    stream = await self._connect(request)
  File "D:\Magang\bot-tele\venv\lib\site-packages\httpcore\_async\connection.py", line 122, in _connect
    stream = await self._network_backend.connect_tcp(**kwargs)
  File "D:\Magang\bot-tele\venv\lib\site-packages\httpcore\_backends\auto.py", line 30, in connect_tcp
    return await self._backend.connect_tcp(
  File "D:\Magang\bot-tele\venv\lib\site-packages\httpcore\_backends\anyio.py", line 115, in connect_tcp
    with map_exceptions(exc_map):
  File "C:\Users\kahfi\AppData\Local\Programs\Python\Python310\lib\contextlib.py", line 153, in __exit__
    self.gen.throw(typ, value, traceback)
  File "D:\Magang\bot-tele\venv\lib\site-packages\httpcore\_exceptions.py", line 14, in map_exceptions
    raise to_exc(exc) from exc
httpcore.ConnectError: [Errno 11001] getaddrinfo failed

The above exception was the direct cause of the following exception:

Traceback (most recent call last):
  File "D:\Magang\bot-tele\venv\lib\site-packages\telegram\request\_httpxrequest.py", line 292, in do_request
    res = await self._client.request(
  File "D:\Magang\bot-tele\venv\lib\site-packages\httpx\_client.py", line 1585, in request
    return await self.send(request, auth=auth, follow_redirects=follow_redirects)
  File "D:\Magang\bot-tele\venv\lib\site-packages\httpx\_client.py", line 1674, in send
    response = await self._send_handling_auth(
  File "D:\Magang\bot-tele\venv\lib\site-packages\httpx\_client.py", line 1702, in _send_handling_auth
    response = await self._send_handling_redirects(
  File "D:\Magang\bot-tele\venv\lib\site-packages\httpx\_client.py", line 1739, in _send_handling_redirects
    response = await self._send_single_request(request)
  File "D:\Magang\bot-tele\venv\lib\site-packages\httpx\_client.py", line 1776, in _send_single_request
    response = await transport.handle_async_request(request)
  File "D:\Magang\bot-tele\venv\lib\site-packages\httpx\_transports\default.py", line 376, in handle_async_request
    with map_httpcore_exceptions():
  File "C:\Users\kahfi\AppData\Local\Programs\Python\Python310\lib\contextlib.py", line 153, in __exit__
    self.gen.throw(typ, value, traceback)
  File "D:\Magang\bot-tele\venv\lib\site-packages\httpx\_transports\default.py", line 89, in map_httpcore_exceptions
    raise mapped_exc(message) from exc
httpx.ConnectError: [Errno 11001] getaddrinfo failed

The above exception was the direct cause of the following exception:

Traceback (most recent call last):
  File "D:\Magang\bot-tele\venv\lib\site-packages\telegram\ext\_updater.py", line 753, in _network_loop_retry
    if not await do_action():
  File "D:\Magang\bot-tele\venv\lib\site-packages\telegram\ext\_updater.py", line 747, in do_action
    return action_cb_task.result()
  File "D:\Magang\bot-tele\venv\lib\site-packages\telegram\ext\_updater.py", line 377, in polling_action_cb
    updates = await self.bot.get_updates(
  File "D:\Magang\bot-tele\venv\lib\site-packages\telegram\ext\_extbot.py", line 649, in get_updates
    updates = await super().get_updates(
  File "D:\Magang\bot-tele\venv\lib\site-packages\telegram\_bot.py", line 4366, in get_updates
    await self._post(
  File "D:\Magang\bot-tele\venv\lib\site-packages\telegram\_bot.py", line 623, in _post
    return await self._do_post(
  File "D:\Magang\bot-tele\venv\lib\site-packages\telegram\ext\_extbot.py", line 355, in _do_post
    return await super()._do_post(
  File "D:\Magang\bot-tele\venv\lib\site-packages\telegram\_bot.py", line 652, in _do_post
    result = await request.post(
  File "D:\Magang\bot-tele\venv\lib\site-packages\telegram\request\_baserequest.py", line 201, in post
    result = await self._request_wrapper(
  File "D:\Magang\bot-tele\venv\lib\site-packages\telegram\request\_baserequest.py", line 333, in _request_wrapper
    code, payload = await self.do_request(
  File "D:\Magang\bot-tele\venv\lib\site-packages\telegram\request\_httpxrequest.py", line 316, in do_request
    raise NetworkError(f"httpx.{err.__class__.__name__}: {err}") from err
telegram.error.NetworkError: httpx.ConnectError: [Errno 11001] getaddrinfo failed
2024-12-02 09:43:50,057 - httpx - INFO - HTTP Request: POST https://api.telegram.org/bot7617596594:AAFyiPhJU4lcaBsbFgdTjdxKPPXV4dHiUqI/sendMessage "HTTP/1.1 200 OK"
2024-12-02 09:43:54,814 - httpx - INFO - HTTP Request: POST https://api.telegram.org/bot7617596594:AAFyiPhJU4lcaBsbFgdTjdxKPPXV4dHiUqI/getUpdates "HTTP/1.1 200 OK"
2024-12-02 09:43:55,247 - httpx - INFO - HTTP Request: POST https://api.telegram.org/bot7617596594:AAFyiPhJU4lcaBsbFgdTjdxKPPXV4dHiUqI/sendMessage "HTTP/1.1 200 OK"
2024-12-02 09:43:56,630 - httpx - INFO - HTTP Request: POST https://api.telegram.org/bot7617596594:AAFyiPhJU4lcaBsbFgdTjdxKPPXV4dHiUqI/sendMessage "HTTP/1.1 200 OK"
2024-12-02 09:44:01,474 - httpx - INFO - HTTP Request: POST https://api.telegram.org/bot7617596594:AAFyiPhJU4lcaBsbFgdTjdxKPPXV4dHiUqI/getUpdates "HTTP/1.1 200 OK"
2024-12-02 09:44:05,245 - httpx - INFO - HTTP Request: POST https://api.telegram.org/bot7617596594:AAFyiPhJU4lcaBsbFgdTjdxKPPXV4dHiUqI/sendMessage "HTTP/1.1 200 OK"
2024-12-02 09:44:09,163 - httpx - INFO - HTTP Request: POST https://api.telegram.org/bot7617596594:AAFyiPhJU4lcaBsbFgdTjdxKPPXV4dHiUqI/getUpdates "HTTP/1.1 200 OK"
2024-12-02 09:44:13,753 - httpx - INFO - HTTP Request: POST https://api.telegram.org/bot7617596594:AAFyiPhJU4lcaBsbFgdTjdxKPPXV4dHiUqI/sendMessage "HTTP/1.1 200 OK"
2024-12-02 09:44:23,215 - httpx - INFO - HTTP Request: POST https://api.telegram.org/bot7617596594:AAFyiPhJU4lcaBsbFgdTjdxKPPXV4dHiUqI/getUpdates "HTTP/1.1 200 OK"
2024-12-02 09:44:33,439 - httpx - INFO - HTTP Request: POST https://api.telegram.org/bot7617596594:AAFyiPhJU4lcaBsbFgdTjdxKPPXV4dHiUqI/getUpdates "HTTP/1.1 200 OK"
2024-12-02 09:44:43,659 - httpx - INFO - HTTP Request: POST https://api.telegram.org/bot7617596594:AAFyiPhJU4lcaBsbFgdTjdxKPPXV4dHiUqI/getUpdates "HTTP/1.1 200 OK"
2024-12-02 09:44:53,871 - httpx - INFO - HTTP Request: POST https://api.telegram.org/bot7617596594:AAFyiPhJU4lcaBsbFgdTjdxKPPXV4dHiUqI/getUpdates "HTTP/1.1 200 OK"
2024-12-02 09:45:04,743 - httpx - INFO - HTTP Request: POST https://api.telegram.org/bot7617596594:AAFyiPhJU4lcaBsbFgdTjdxKPPXV4dHiUqI/getUpdates "HTTP/1.1 200 OK"
2024-12-02 09:45:04,747 - telegram.ext.Application - INFO - Application is stopping. This might take a moment.
2024-12-02 09:45:04,748 - telegram.ext.Application - INFO - Application.stop() complete
